ort 5432 failed: Connection refused
    Is the server running on that host and accepting TCP/IP connections?
connection to server at "localhost" (::1), port 5432 failed: Cannot assign requested address
    Is the server running on that host and accepting TCP/IP connections?


The above exception was the direct cause of the following exception:

Traceback (most recent call last):
  File "/nix/store/vnvdzw4182wb2ifzi0cczhv80yfnpx1q-python3-3.12.11/lib/python3.12/threading.py", line 1075, in _bootstrap_inner
    self.run()
  File "/nix/store/vnvdzw4182wb2ifzi0cczhv80yfnpx1q-python3-3.12.11/lib/python3.12/threading.py", line 1012, in run
    self._target(*self._args, **self._kwargs)
  File "/home/runner/workspace/.pythonlibs/lib/python3.12/site-packages/django/utils/autoreload.py", line 64, in wrapper
    fn(*args, **kwargs)
  File "/home/runner/workspace/.pythonlibs/lib/python3.12/site-packages/django/core/management/commands/runserver.py", line 137, in inner_run
    self.check_migrations()
  File "/home/runner/workspace/.pythonlibs/lib/python3.12/site-packages/django/core/management/base.py", line 587, in check_migrations
    executor = MigrationExecutor(connections[DEFAULT_DB_ALIAS])
               ^^^^^^^^^^^^^^^^^^^^^^^^^^^^^^^^^^^^^^^^^^^^^^^^
  File "/home/runner/workspace/.pythonlibs/lib/python3.12/site-packages/django/db/migrations/executor.py", line 18, in __init__
    self.loader = MigrationLoader(self.connection)
                  ^^^^^^^^^^^^^^^^^^^^^^^^^^^^^^^^
  File "/home/runner/workspace/.pythonlibs/lib/python3.12/site-packages/django/db/migrations/loader.py", line 58, in __init__
    self.build_graph()
  File "/home/runner/workspace/.pythonlibs/lib/python3.12/site-packages/django/db/migrations/loader.py", line 235, in build_graph
    self.applied_migrations = recorder.applied_migrations()
                              ^^^^^^^^^^^^^^^^^^^^^^^^^^^^^
  File "/home/runner/workspace/.pythonlibs/lib/python3.12/site-packages/django/db/migrations/recorder.py", line 89, in applied_migrations
    if self.has_table():
       ^^^^^^^^^^^^^^^^
  File "/home/runner/workspace/.pythonlibs/lib/python3.12/site-packages/django/db/migrations/recorder.py", line 63, in has_table
    with self.connection.cursor() as cursor:
         ^^^^^^^^^^^^^^^^^^^^^^^^
  File "/home/runner/workspace/.pythonlibs/lib/python3.12/site-packages/django/utils/asyncio.py", line 26, in inner
    return func(*args, **kwargs)
           ^^^^^^^^^^^^^^^^^^^^^
  File "/home/runner/workspace/.pythonlibs/lib/python3.12/site-packages/django/db/backends/base/base.py", line 320, in cursor
    return self._cursor()
           ^^^^^^^^^^^^^^
  File "/home/runner/workspace/.pythonlibs/lib/python3.12/site-packages/django/db/backends/base/base.py", line 296, in _cursor
    self.ensure_connection()
  File "/home/runner/workspace/.pythonlibs/lib/python3.12/site-packages/django/utils/asyncio.py", line 26, in inner
    return func(*args, **kwargs)
           ^^^^^^^^^^^^^^^^^^^^^
  File "/home/runner/workspace/.pythonlibs/lib/python3.12/site-packages/django/db/backends/base/base.py", line 278, in ensure_connection
    with self.wrap_database_errors:
         ^^^^^^^^^^^^^^^^^^^^^^^^^
  File "/home/runner/workspace/.pythonlibs/lib/python3.12/site-packages/django/db/utils.py", line 91, in __exit__
    raise dj_exc_value.with_traceback(traceback) from exc_value
  File "/home/runner/workspace/.pythonlibs/lib/python3.12/site-packages/django/db/backends/base/base.py", line 279, in ensure_connection
    self.connect()
  File "/home/runner/workspace/.pythonlibs/lib/python3.12/site-packages/django/utils/asyncio.py", line 26, in inner
    return func(*args, **kwargs)
           ^^^^^^^^^^^^^^^^^^^^^
  File "/home/runner/workspace/.pythonlibs/lib/python3.12/site-packages/django/db/backends/base/base.py", line 256, in connect
    self.connection = self.get_new_connection(conn_params)
                      ^^^^^^^^^^^^^^^^^^^^^^^^^^^^^^^^^^^^
  File "/home/runner/workspace/.pythonlibs/lib/python3.12/site-packages/django/utils/asyncio.py", line 26, in inner
    return func(*args, **kwargs)
           ^^^^^^^^^^^^^^^^^^^^^
  File "/home/runner/workspace/.pythonlibs/lib/python3.12/site-packages/django/db/backends/postgresql/base.py", line 332, in get_new_connection
    connection = self.Database.connect(**conn_params)
                 ^^^^^^^^^^^^^^^^^^^^^^^^^^^^^^^^^^^^
  File "/home/runner/workspace/.pythonlibs/lib/python3.12/site-packages/psycopg2/__init__.py", line 122, in connect
    conn = _connect(dsn, connection_factory=connection_factory, **kwasync)
           ^^^^^^^^^^^^^^^^^^^^^^^^^^^^^^^^^^^^^^^^^^^^^^^^^^^^^^^^^^^^^^^
django.db.utils.OperationalError: connection to server at "localhost" (127.0.0.1), port 5432 failed: Connection refused
    Is the server running on that host and accepting TCP/IP connections?
connection to server at "localhost" (::1), port 5432 failed: Cannot assign requested address
    Is the server running on that host and accepting TCP/IP connections?
